# Exceptions
***
> main -> f1 -> f2 -> ... -> f5 -> ... -> f9 -> f10  
>....................................catch................throw

```c++
int f(int a, int b) {
    if (b == 0) throw 1; // very bad, throwing int is stupid
    return a / b;
}

int main() {
    int x;;
    int y;
    
    std::cin >> x >> y; // 2 0
    try {
        int z = f(x, y); // CE
    // terminate called after throwing an instance of 'int'
    } catch(int err) {
        std::cout << "Oops! " << err << '\n'; // Oops! 1
    } catch(string str) {
        ...;
    } cathc(...) {
        ...;
    }
    
    std::cout << z << '\n'; 
}
```

> обертку try - catch нужно писать только над ф-ией которая может обработать исключение
> после try всегда есть catch

```c++
int* p = new(std::nothrow) int[1000000000000];
int* p = new int[1'000'000'000]; // std::bad_alloc
// std::bad_cast
```