# Deep diving into throwing and catching
***

> Что происходит при ``throw`` и ``catch``
```c++
void f(int a) {
    std::string abc = "aaaaa";
    
    ...;
    
    
    throw abc; // what happens? 
    // abc copies (moves)
    // no way to throw string& abc
    // 
}


int main() {
    try {
        f(1);
    } cathc(std::string str) { // copies again
        ...;
    }
    
    try {
        f(1;)
    } catch(const std::string& str) { // doesn't copy again
        ...
    }
}
```

> how to catch other types  
> в ``catch`` нет приведения типов, просто проверяется совпал тип или нет  
> кроме кроме  
> от наследника к родителю
> 
```c++
int main() {
    try {
        throw std::runtime_error("aaa");
    } catch(const std::exception& s) {
        std::cout << "Oops! " << '\n';
        throw s; // пошлет срезку
        throw; // пошлет runtime_error
    } catch(std::runtime_error& d) { // этот код не достижим
        std::cout << "AAAA!!!" << '\n';
    }
}
```