# RAII
***
### resource acquisition is initialization
```c++
void f(int x) {
    int* p = new int(5);
    
    if (x == 0) throw std::runtime_error("Oops!");

    delete p;
}

int main() {
    try {
        f(0); // memory leak
    } catch (std::exception& ex) {
        std::cout << ex.what();
    }
}
```
### SmartPtr

```c++
struct SmartPtr {
    int* ptr;
    SmartPtr(int* ptr): ptr(ptr) {}
    ~SmartPtr() {
        delete ptr;
    } 
};

void f(int x) {
    SmartPtr p = new int(5);
    
    if (x == 0) throw std::runtime_error("Oops!");
}

int main() {
    try {
        f(0); // memory leak
    } catch (std::exception& ex) {
        std::cout << ex.what();
    }
}
```

### unique_ptr, shared_ptr - поддерживают копирование

### Exceptions in constructors and destructors

```c++
class MyClass {
    std::string str;
    int* p;
public:
    MyClass(const std::string& str): str(str), p(new int(5)) {
        if (str.size) == 0) {
            throw std::logic_error("AAAA!");
        }
    } 
    ~MyClass() {
        
        if (str.size() == 1) {
            throw std::logic_error("afdsf");
        } // aborted core dumped
        
        delete p;
    }
};


void f(int x) {
    MyClass a = MyClass(""); // memory leak
    
}
```
> компилятор не поддерживает два летящих одновременно исключения
>

```c++
//since c++11 из деструкторов нельзя кидать исключения
// но если оч хочется - можно

~T() noexcept(false) {
    ...
}
```

```c++
std::uncaught_exception() // -- bool ф-ия есть ли летящее сейчас исключение
```


```c++
//function try block
MyClass(...) try: ..., ... {
    ...;
} catch (...) {
    ...;
}


int main() try {
    ...;
} catch (...) {
    ...;
}
```